Workbook

Sheet LG
B2: LG
B4: CODIGO | C4: DESCRIPCION | D4: STOCK JUEGOS | E4: STOCK BARRAS | F4: "J" PRECIO VENTA | G4: "J"PRECIO COMPRA | H4: BARRAS | I4: "B"PRECIO VENTA | J4: "B"PRECIO COMPRA | K4: ENTRADAS JUEGOS | L4: ENTRADAS BARRAS | M4: SALIDAS JUEGOS | N4: SALIDA BARRAS | O4: CAPITAL JUEGOS | P4: CAPITAL/GANANCIA/JUEGOS | Q4: CAPITAL BARRA | R4: CAP GAN BARRAS | S4: CANTIDAD INICIAL JUEGO | T4: CANTIDAD INICIAL BARRAS | U4: PRECIO EN $ | V4: CODIGO 2 | W4: CODIGO 3
A5: 1 | B5: 1000 | C5: 32 LA -3B/3V/7-7L | D5: =(LG26V[[#This Row],[CANTIDAD INICIAL JUEGO ]]+LG26V[[#This Row],[ENTRADAS JUEGOS ]]-LG26V[[#This Row],[SALIDAS JUEGOS]]) -> 21 | E5: =(LG26V[[#This Row],[CANTIDAD INICIAL BARRAS]]+LG26V[[#This Row],[ENTRADAS BARRAS]]-LG26V[[#This Row],[SALIDA BARRAS]]) -> 1 | F5: 80 | G5: 43 | H5: 3 | I5: =(LG26V[[#This Row],["J" PRECIO VENTA ]]/LG26V[[#This Row],[BARRAS]]) -> 26.666667 | J5: =(LG26V[[#This Row],["J"PRECIO COMPRA ]]/LG26V[[#This Row],[BARRAS]]) -> 14.333333 | K5: =SUMIF(entradas26[CODIGO],LG26V[[#This Row],[CODIGO ]],entradas26[[CAN JUEGOS ]]) -> 20 | L5: =SUMIF(entradas26[CODIGO],LG26V[[#This Row],[CODIGO ]],entradas26[CAN BARRAS]) -> 0 | M5: =SUMIF(salidas26[[CODIGO ]],LG26V[[#This Row],[CODIGO ]],salidas26[[CANT JUEGOS ]]) -> 8 | N5: =SUMIF(salidas26[[CODIGO ]],LG26V[[#This Row],[CODIGO ]],salidas26[CANT BARRAS]) -> 0 | O5: =(LG26V[[#This Row],["J"PRECIO COMPRA ]]*LG26V[[#This Row],[STOCK JUEGOS]]) -> 903 | P5: =(LG26V[[#This Row],["J" PRECIO VENTA ]]*LG26V[[#This Row],[STOCK JUEGOS]]) -> 1680 | Q5: =(LG26V[[#This Row],["B"PRECIO COMPRA]]*LG26V[[#This Row],[STOCK BARRAS]]) -> 14.333333 | R5: =(LG26V[[#This Row],["B"PRECIO VENTA ]]*LG26V[[#This Row],[STOCK BARRAS]]) -> 26.666667 | S5: 9 | T5: 1 | U5: 1.8 | W5: XLM-0001
A6: 2 | B6: 1003 | C6: 32 LA -3B/3V/7-8-7L | D6: =(LG26V[[#This Row],[CANTIDAD INICIAL JUEGO ]]+LG26V[[#This Row],[ENTRADAS JUEGOS ]]-LG26V[[#This Row],[SALIDAS JUEGOS]]) -> -3 | E6: =(LG26V[[#This Row],[CANTIDAD INICIAL BARRAS]]+LG26V[[#This Row],[ENTRADAS BARRAS]]-LG26V[[#This Row],[SALIDA BARRAS]]) -> 2 | F6: 80 | G6: 30 | H6: 3 | I6: =(LG26V[[#This Row],["J" PRECIO VENTA ]]/LG26V[[#This Row],[BARRAS]]) -> 26.666667 | J6: =(LG26V[[#This Row],["J"PRECIO COMPRA ]]/LG26V[[#This Row],[BARRAS]]) -> 10 | K6: =SUMIF(entradas26[CODIGO],LG26V[[#This Row],[CODIGO ]],entradas26[[CAN JUEGOS ]]) -> 0 | L6: =SUMIF(entradas26[CODIGO],LG26V[[#This Row],[CODIGO ]],entradas26[CAN BARRAS]) -> 0 | M6: =SUMIF(salidas26[[CODIGO ]],LG26V[[#This Row],[CODIGO ]],salidas26[[CANT JUEGOS ]]) -> 10 | N6: =SUMIF(salidas26[[CODIGO ]],LG26V[[#This Row],[CODIGO ]],salidas26[CANT BARRAS]) -> 0 | O6: =(LG26V[[#This Row],["J"PRECIO COMPRA ]]*LG26V[[#This Row],[STOCK JUEGOS]]) -> -90 | P6: =(LG26V[[#This Row],["J" PRECIO VENTA ]]*LG26V[[#This Row],[STOCK JUEGOS]]) -> -240 | Q6: =(LG26V[[#This Row],["B"PRECIO COMPRA]]*LG26V[[#This Row],[STOCK BARRAS]]) -> 20 | R6: =(LG26V[[#This Row],["B"PRECIO VENTA ]]*LG26V[[#This Row],[STOCK BARRAS]]) -> 53.333333 | S6: 7 | T6: 2 | U6: 1.38 | W6: XY-0012-A2
A7: 3 | B7: 1006 | C7: 32 LA -3B/3V/8-8-8 | D7: =(LG26V[[#This Row],[CANTIDAD INICIAL JUEGO ]]+LG26V[[#This Row],[ENTRADAS JUEGOS ]]-LG26V[[#This Row],[SALIDAS JUEGOS]]) -> 31 | E7: =(LG26V[[#This Row],[CANTIDAD INICIAL BARRAS]]+LG26V[[#This Row],[ENTRADAS BARRAS]]-LG26V[[#This Row],[SALIDA BARRAS]]) -> 1 | F7: 80 | G7: 48 | H7: 3 | I7: =(LG26V[[#This Row],["J" PRECIO VENTA ]]/LG26V[[#This Row],[BARRAS]]) -> 26.666667 | J7: =(LG26V[[#This Row],["J"PRECIO COMPRA ]]/LG26V[[#This Row],[BARRAS]]) -> 16 | K7: =SUMIF(entradas26[CODIGO],LG26V[[#This Row],[CODIGO ]],entradas26[[CAN JUEGOS ]]) -> 20 | L7: =SUMIF(entradas26[CODIGO],LG26V[[#This Row],[CODIGO ]],entradas26[CAN BARRAS]) -> 0 | M7: =SUMIF(salidas26[[CODIGO ]],LG26V[[#This Row],[CODIGO ]],salidas26[[CANT JUEGOS ]]) -> 1 | N7: =SUMIF(salidas26[[CODIGO ]],LG26V[[#This Row],[CODIGO ]],salidas26[CANT BARRAS]) -> 0 | O7: =(LG26V[[#This Row],["J"PRECIO COMPRA ]]*LG26V[[#This Row],[STOCK JUEGOS]]) -> 1488 | P7: =(LG26V[[#This Row],["J" PRECIO VENTA ]]*LG26V[[#This Row],[STOCK JUEGOS]]) -> 2480 | Q7: =(LG26V[[#This Row],["B"PRECIO COMPRA]]*LG26V[[#This Row],[STOCK BARRAS]]) -> 16 | R7: =(LG26V[[#This Row],["B"PRECIO VENTA ]]*LG26V[[#This Row],[STOCK BARRAS]]) -> 26.666667 | S7: 12 | T7: 1 | U7: 1.8 | W7: XLM-0026
A8: 5 | B8: 1011 | C8: 32LK540 6L/3V /2B | D8: =(LG26V[[#This Row],[CANTIDAD INICIAL JUEGO ]]+LG26V[[#This Row],[ENTRADAS JUEGOS ]]-LG26V[[#This Row],[SALIDAS JUEGOS]]) -> 0 | E8: =(LG26V[[#This Row],[CANTIDAD INICIAL BARRAS]]+LG26V[[#This Row],[ENTRADAS BARRAS]]-LG26V[[#This Row],[SALIDA BARRAS]]) -> 0 | F8: 70 | G8: 30 | H8: 2 | I8: =(LG26V[[#This Row],["J" PRECIO VENTA ]]/LG26V[[#This Row],[BARRAS]]) -> 35 | J8: =(LG26V[[#This Row],["J"PRECIO COMPRA ]]/LG26V[[#This Row],[BARRAS]]) -> 15 | K8: =SUMIF(entradas26[CODIGO],LG26V[[#This Row],[CODIGO ]],entradas26[[CAN JUEGOS ]]) -> 0 | L8: =SUMIF(entradas26[CODIGO],LG26V[[#This Row],[CODIGO ]],entradas26[CAN BARRAS]) -> 0 | M8: =SUMIF(salidas26[[CODIGO ]],LG26V[[#This Row],[CODIGO ]],salidas26[[CANT JUEGOS ]]) -> 8 | N8: =SUMIF(salidas26[[CODIGO ]],LG26V[[#This Row],[CODIGO ]],salidas26[CANT BARRAS]) -> 0 | O8: =(LG26V[[#This Row],["J"PRECIO COMPRA ]]*LG26V[[#This Row],[STOCK JUEGOS]]) -> 0 | P8: =(LG26V[[#This Row],["J" PRECIO VENTA ]]*LG26V[[#This Row],[STOCK JUEGOS]]) -> 0 | Q8: =(LG26V[[#This Row],["B"PRECIO COMPRA]]*LG26V[[#This Row],[STOCK BARRAS]]) -> 0 | R8: =(LG26V[[#This Row],["B"PRECIO VENTA ]]*LG26V[[#This Row],[STOCK BARRAS]]) -> 0 | S8: 8 | U8: 1.3 | W8: XY-0229
A9: 6 | B9: 1012 | C9: 32LB620B-32LF620B -3B/6V/6L | D9: =(LG26V[[#This Row],[CANTIDAD INICIAL JUEGO ]]+LG26V[[#This Row],[ENTRADAS JUEGOS ]]-LG26V[[#This Row],[SALIDAS JUEGOS]]) -> 13 | E9: =(LG26V[[#This Row],[CANTIDAD INICIAL BARRAS]]+LG26V[[#This Row],[ENTRADAS BARRAS]]-LG26V[[#This Row],[SALIDA BARRAS]]) -> 0 | F9: 90 | G9: 69 | H9: 3 | I9: =(LG26V[[#This Row],["J" PRECIO VENTA ]]/LG26V[[#This Row],[BARRAS]]) -> 30 | J9: =(LG26V[[#This Row],["J"PRECIO COMPRA ]]/LG26V[[#This Row],[BARRAS]]) -> 23 | K9: =SUMIF(entradas26[CODIGO],LG26V[[#This Row],[CODIGO ]],entradas26[[CAN JUEGOS ]]) -> 0 | L9: =SUMIF(entradas26[CODIGO],LG26V[[#This Row],[CODIGO ]],entradas26[CAN BARRAS]) -> 0 | M9: =SUMIF(salidas26[[CODIGO ]],LG26V[[#This Row],[CODIGO ]],salidas26[[CANT JUEGOS ]]) -> 21 | N9: =SUMIF(salidas26[[CODIGO ]],LG26V[[#This Row],[CODIGO ]],salidas26[CANT BARRAS]) -> 0 | O9: =(LG26V[[#This Row],["J"PRECIO COMPRA ]]*LG26V[[#This Row],[STOCK JUEGOS]]) -> 897 | P9: =(LG26V[[#This Row],["J" PRECIO VENTA ]]*LG26V[[#This Row],[STOCK JUEGOS]]) -> 1170 | Q9: =(LG26V[[#This Row],["B"PRECIO COMPRA]]*LG26V[[#This Row],[STOCK BARRAS]]) -> 0 | R9: =(LG26V[[#This Row],["B"PRECIO VENTA ]]*LG26V[[#This Row],[STOCK BARRAS]]) -> 0 | S9: 34 | U9: 2.5 | W9: XLM-0269
A10: 7 | B10: 1015 | C10: 32LH500B-32LK500 3B/7L/3V | D10: =(LG26V[[#This Row],[CANTIDAD INICIAL JUEGO ]]+LG26V[[#This Row],[ENTRADAS JUEGOS ]]-LG26V[[#This Row],[SALIDAS JUEGOS]]) -> 10 | E10: =(LG26V[[#This Row],[CANTIDAD INICIAL BARRAS]]+LG26V[[#This Row],[ENTRADAS BARRAS]]-LG26V[[#This Row],[SALIDA BARRAS]]) -> 0 | F10: 80 | G10: 34.2 | H10: 3 | I10: =(LG26V[[#This Row],["J" PRECIO VENTA ]]/LG26V[[#This Row],[BARRAS]]) -> 26.666667 | J10: =(LG26V[[#This Row],["J"PRECIO COMPRA ]]/LG26V[[#This Row],[BARRAS]]) -> 11.4 | K10: =SUMIF(entradas26[CODIGO],LG26V[[#This Row],[CODIGO ]],entradas26[[CAN JUEGOS ]]) -> 20 | L10: =SUMIF(entradas26[CODIGO],LG26V[[#This Row],[CODIGO ]],entradas26[CAN BARRAS]) -> 3 | M10: =SUMIF(salidas26[[CODIGO ]],LG26V[[#This Row],[CODIGO ]],salidas26[[CANT JUEGOS ]]) -> 35 | N10: =SUMIF(salidas26[[CODIGO ]],LG26V[[#This Row],[CODIGO ]],salidas26[CANT BARRAS]) -> 5 | O10: =(LG26V[[#This Row],["J"PRECIO COMPRA ]]*LG26V[[#This Row],[STOCK JUEGOS]]) -> 342 | P10: =(LG26V[[#This Row],["J" PRECIO VENTA ]]*LG26V[[#This Row],[STOCK JUEGOS]]) -> 800 | Q10: =(LG26V[[#This Row],["B"PRECIO COMPRA]]*LG26V[[#This Row],[STOCK BARRAS]]) -> 0 | R10: =(LG26V[[#This Row],["B"PRECIO VENTA ]]*LG26V[[#This Row],[STOCK BARRAS]]) -> 0 | S10: 25 | T10: 2 | U10: 1.8 | W10: XLM-0329
A11: 8 | B11: 1018 | C11: 32 LH 5100-2B/5L | D11: =(LG26V[[#This Row],[CANTIDAD INICIAL JUEGO ]]+LG26V[[#This Row],[ENTRADAS JUEGOS ]]-LG26V[[#This Row],[SALIDAS JUEGOS]]) -> 15 | E11: =(LG26V[[#This Row],[CANTIDAD INICIAL BARRAS]]+LG26V[[#This Row],[ENTRADAS BARRAS]]-LG26V[[#This Row],[SALIDA BARRAS]]) -> 0 | F11: 80 | G11: 38 | H11: 2 | I11: =(LG26V[[#This Row],["J" PRECIO VENTA ]]/LG26V[[#This Row],[BARRAS]]) -> 40 | J11: =(LG26V[[#This Row],["J"PRECIO COMPRA ]]/LG26V[[#This Row],[BARRAS]]) -> 19 | K11: =SUMIF(entradas26[CODIGO],LG26V[[#This Row],[CODIGO ]],entradas26[[CAN JUEGOS ]]) -> 0 | L11: =SUMIF(entradas26[CODIGO],LG26V[[#This Row],[CODIGO ]],entradas26[CAN BARRAS]) -> 0 | M11: =SUMIF(salidas26[[CODIGO ]],LG26V[[#This Row],[CODIGO ]],salidas26[[CANT JUEGOS ]]) -> 3 | N11: =SUMIF(salidas26[[CODIGO ]],LG26V[[#This Row],[CODIGO ]],salidas26[CANT BARRAS]) -> 0 | O11: =(LG26V[[#This Row],["J"PRECIO COMPRA ]]*LG26V[[#This Row],[STOCK JUEGOS]]) -> 570 | P11: =(LG26V[[#This Row],["J" PRECIO VENTA ]]*LG26V[[#This Row],[STOCK JUEGOS]]) -> 1200 | Q11: =(LG26V[[#This Row],["B"PRECIO COMPRA]]*LG26V[[#This Row],[STOCK BARRAS]]) -> 0 | R11: =(LG26V[[#This Row],["B"PRECIO VENTA ]]*LG26V[[#This Row],[STOCK BARRAS]]) -> 0 | S11: 18 | U11: 1.45 | W11: XLM-270
A12: 9 | B12: 1021 | C12: 32LS3450-4B/7L POLA | D12: =(LG26V[[#This Row],[CANTIDAD INICIAL JUEGO ]]+LG26V[[#This Row],[ENTRADAS JUEGOS ]]-LG26V[[#This Row],[SALIDAS JUEGOS]]) -> 1 | E12: =(LG26V[[#This Row],[CANTIDAD INICIAL BARRAS]]+LG26V[[#This Row],[ENTRADAS BARRAS]]-LG26V[[#This Row],[SALIDA BARRAS]]) -> 0 | F12: 120 | G12: 80 | H12: 4 | I12: =(LG26V[[#This Row],["J" PRECIO VENTA ]]/LG26V[[#This Row],[BARRAS]]) -> 30 | J12: =(LG26V[[#This Row],["J"PRECIO COMPRA ]]/LG26V[[#This Row],[BARRAS]]) -> 20 | K12: =SUMIF(entradas26[CODIGO],LG26V[[#This Row],[CODIGO ]],entradas26[[CAN JUEGOS ]]) -> 0 | L12: =SUMIF(entradas26[CODIGO],LG26V[[#This Row],[CODIGO ]],entradas26[CAN BARRAS]) -> 0 | M12: =SUMIF(salidas26[[CODIGO ]],LG26V[[#This Row],[CODIGO ]],salidas26[[CANT JUEGOS ]]) -> 0 | N12: =SUMIF(salidas26[[CODIGO ]],LG26V[[#This Row],[CODIGO ]],salidas26[CANT BARRAS]) -> 0 | O12: =(LG26V[[#This Row],["J"PRECIO COMPRA ]]*LG26V[[#This Row],[STOCK JUEGOS]]) -> 80 | P12: =(LG26V[[#This Row],["J" PRECIO VENTA ]]*LG26V[[#This Row],[STOCK JUEGOS]]) -> 120 | Q12: =(LG26V[[#This Row],["B"PRECIO COMPRA]]*LG26V[[#This Row],[STOCK BARRAS]]) -> 0 | R12: =(LG26V[[#This Row],["B"PRECIO VENTA ]]*LG26V[[#This Row],[STOCK BARRAS]]) -> 0 | S12: 1
A13: 10 | B13: 1024 | C13: 32LN5100- 3B/6L-6-7-6 POLA | D13: =(LG26V[[#This Row],[CANTIDAD INICIAL JUEGO ]]+LG26V[[#This Row],[ENTRADAS JUEGOS ]]-LG26V[[#This Row],[SALIDAS JUEGOS]]) -> 18 | E13: =(LG26V[[#This Row],[CANTIDAD INICIAL BARRAS]]+LG26V[[#This Row],[ENTRADAS BARRAS]]-LG26V[[#This Row],[SALIDA BARRAS]]) -> 0 | F13: 100 | G13: 64 | H13: 3 | I13: =(LG26V[[#This Row],["J" PRECIO VENTA ]]/LG26V[[#This Row],[BARRAS]]) -> 33.333333 | J13: =(LG26V[[#This Row],["J"PRECIO COMPRA ]]/LG26V[[#This Row],[BARRAS]]) -> 21.333333 | K13: =SUMIF(entradas26[CODIGO],LG26V[[#This Row],[CODIGO ]],entradas26[[CAN JUEGOS ]]) -> 0 | L13: =SUMIF(entradas26[CODIGO],LG26V[[#This Row],[CODIGO ]],entradas26[CAN BARRAS]) -> 0 | M13: =SUMIF(salidas26[[CODIGO ]],LG26V[[#This Row],[CODIGO ]],salidas26[[CANT JUEGOS ]]) -> 4 | N13: =SUMIF(salidas26[[CODIGO ]],LG26V[[#This Row],[CODIGO ]],salidas26[CANT BARRAS]) -> 0 | O13: =(LG26V[[#This Row],["J"PRECIO COMPRA ]]*LG26V[[#This Row],[STOCK JUEGOS]]) -> 1152 | P13: =(LG26V[[#This Row],["J" PRECIO VENTA ]]*LG26V[[#This Row],[STOCK JUEGOS]]) -> 1800 | Q13: =(LG26V[[#This Row],["B"PRECIO COMPRA]]*LG26V[[#This Row],[STOCK BARRAS]]) -> 0 | R13: =(LG26V[[#This Row],["B"PRECIO VENTA ]]*LG26V[[#This Row],[STOCK BARRAS]]) -> 0 | S13: 22 | U13: 2.4 | W13: XLM-0254/0255
A14: 11 | B14: 1027 | C14: 32LM3400-4B/3V/9L | D14: =(LG26V[[#This Row],[CANTIDAD INICIAL JUEGO ]]+LG26V[[#This Row],[ENTRADAS JUEGOS ]]-LG26V[[#This Row],[SALIDAS JUEGOS]]) -> 26 | E14: =(LG26V[[#This Row],[CANTIDAD INICIAL BARRAS]]+LG26V[[#This Row],[ENTRADAS BARRAS]]-LG26V[[#This Row],[SALIDA BARRAS]]) -> 0 | F14: 120 | G14: 70 | H14: 4 | I14: =(LG26V[[#This Row],["J" PRECIO VENTA ]]/LG26V[[#This Row],[BARRAS]]) -> 30 | J14: =(LG26V[[#This Row],["J"PRECIO COMPRA ]]/LG26V[[#This Row],[BARRAS]]) -> 17.5 | K14: =SUMIF(entradas26[CODIGO],LG26V[[#This Row],[CODIGO ]],entradas26[[CAN JUEGOS ]]) -> 20 | L14: =SUMIF(entradas26[CODIGO],LG26V[[#This Row],[CODIGO ]],entradas26[CAN BARRAS]) -> 0 | M14: =SUMIF(salidas26[[CODIGO ]],LG26V[[#This Row],[CODIGO ]],salidas26[[CANT JUEGOS ]]) -> 4 | N14: =SUMIF(salidas26[[CODIGO ]],LG26V[[#This Row],[CODIGO ]],salidas26[CANT BARRAS]) -> 0 | O14: =(LG26V[[#This Row],["J"PRECIO COMPRA ]]*LG26V[[#This Row],[STOCK JUEGOS]]) -> 1820 | P14: =(LG26V[[#This Row],["J" PRECIO VENTA ]]*LG26V[[#This Row],[STOCK JUEGOS]]) -> 3120 | Q14: =(LG26V[[#This Row],["B"PRECIO COMPRA]]*LG26V[[#This Row],[STOCK BARRAS]]) -> 0 | R14: =(LG26V[[#This Row],["B"PRECIO VENTA ]]*LG26V[[#This Row],[STOCK BARRAS]]) -> 0 | S14: 10 | U14: 3.7 | W14: XLM-0103-0104
A15: 12 | B15: 1028 | C15: 29 LG/ 1B | D15: =(LG26V[[#This Row],[CANTIDAD INICIAL JUEGO ]]+LG26V[[#This Row],[ENTRADAS JUEGOS ]]-LG26V[[#This Row],[SALIDAS JUEGOS]]) -> 3 | E15: =(LG26V[[#This Row],[CANTIDAD INICIAL BARRAS]]+LG26V[[#This Row],[ENTRADAS BARRAS]]-LG26V[[#This Row],[SALIDA BARRAS]]) -> 0 | F15: 90 | G15: 50 | H15: 1 | I15: =(LG26V[[#This Row],["J" PRECIO VENTA ]]/LG26V[[#This Row],[BARRAS]]) -> 90 | J15: =(LG26V[[#This Row],["J"PRECIO COMPRA ]]/LG26V[[#This Row],[BARRAS]]) -> 50 | K15: =SUMIF(entradas26[CODIGO],LG26V[[#This Row],[CODIGO ]],entradas26[[CAN JUEGOS ]]) -> 0 | L15: =SUMIF(entradas26[CODIGO],LG26V[[#This Row],[CODIGO ]],entradas26[CAN BARRAS]) -> 0 | M15: =SUMIF(salidas26[[CODIGO ]],LG26V[[#This Row],[CODIGO ]],salidas26[[CANT JUEGOS ]]) -> 0 | N15: =SUMIF(salidas26[[CODIGO ]],LG26V[[#This Row],[CODIGO ]],salidas26[CANT BARRAS]) -> 0 | O15: =(LG26V[[#This Row],["J"PRECIO COMPRA ]]*LG26V[[#This Row],[STOCK JUEGOS]]) -> 150 | P15: =(LG26V[[#This Row],["J" PRECIO VENTA ]]*LG26V[[#This Row],[STOCK JUEGOS]]) -> 270 | Q15: =(LG26V[[#This Row],["B"PRECIO COMPRA]]*LG26V[[#This Row],[STOCK BARRAS]]) -> 0 | R15: =(LG26V[[#This Row],["B"PRECIO VENTA ]]*LG26V[[#This Row],[STOCK BARRAS]]) -> 0 | S15: 3
A16: 13 | B16: 1030 | C16: 40 LB6450/8B/6V | D16: =(LG26V[[#This Row],[CANTIDAD INICIAL JUEGO ]]+LG26V[[#This Row],[ENTRADAS JUEGOS ]]-LG26V[[#This Row],[SALIDAS JUEGOS]]) -> 9 | E16: =(LG26V[[#This Row],[CANTIDAD INICIAL BARRAS]]+LG26V[[#This Row],[ENTRADAS BARRAS]]-LG26V[[#This Row],[SALIDA BARRAS]]) -> 0 | F16: 200 | G16: 110 | H16: 8 | I16: =(LG26V[[#This Row],["J" PRECIO VENTA ]]/LG26V[[#This Row],[BARRAS]]) -> 25 | J16: =(LG26V[[#This Row],["J"PRECIO COMPRA ]]/LG26V[[#This Row],[BARRAS]]) -> 13.75 | K16: =SUMIF(entradas26[CODIGO],LG26V[[#This Row],[CODIGO ]],entradas26[[CAN JUEGOS ]]) -> 0 | L16: =SUMIF(entradas26[CODIGO],LG26V[[#This Row],[CODIGO ]],entradas26[CAN BARRAS]) -> 0 | M16: =SUMIF(salidas26[[CODIGO ]],LG26V[[#This Row],[CODIGO ]],salidas26[[CANT JUEGOS ]]) -> 0 | N16: =SUMIF(salidas26[[CODIGO ]],LG26V[[#This Row],[CODIGO ]],salidas26[CANT BARRAS]) -> 0 | O16: =(LG26V[[#This Row],["J"PRECIO COMPRA ]]*LG26V[[#This Row],[STOCK JUEGOS]]) -> 990 | P16: =(LG26V[[#This Row],["J" PRECIO VENTA ]]*LG26V[[#This Row],[STOCK JUEGOS]]) -> 1800 | Q16: =(LG26V[[#This Row],["B"PRECIO COMPRA]]*LG26V[[#This Row],[STOCK BARRAS]]) -> 0 | R16: =(LG26V[[#This Row],["B"PRECIO VENTA ]]*LG26V[[#This Row],[STOCK BARRAS]]) -> 0 | S16: 9 | U16: 5.5 | W16: XLM-0277/0278
A17: 14 | B17: 1033 | C17: 42LB6200-42LF6200 8B/6V | D17: =(LG26V[[#This Row],[CANTIDAD INICIAL JUEGO ]]+LG26V[[#This Row],[ENTRADAS JUEGOS ]]-LG26V[[#This Row],[SALIDAS JUEGOS]]) -> 18 | E17: =(LG26V[[#This Row],[CANTIDAD INICIAL BARRAS]]+LG26V[[#This Row],[ENTRADAS BARRAS]]-LG26V[[#This Row],[SALIDA BARRAS]]) -> 0 | F17: 180 | G17: 130 | H17: 8 | I17: =(LG26V[[#This Row],["J" PRECIO VENTA ]]/LG26V[[#This Row],[BARRAS]]) -> 22.5 | J17: =(LG26V[[#This Row],["J"PRECIO COMPRA ]]/LG26V[[#This Row],[BARRAS]]) -> 16.25 | K17: =SUMIF(entradas26[CODIGO],LG26V[[#This Row],[CODIGO ]],entradas26[[CAN JUEGOS ]]) -> 23 | L17: =SUMIF(entradas26[CODIGO],LG26V[[#This Row],[CODIGO ]],entradas26[CAN BARRAS]) -> 0 | M17: =SUMIF(salidas26[[CODIGO ]],LG26V[[#This Row],[CODIGO ]],salidas26[[CANT JUEGOS ]]) -> 29 | N17: =SUMIF(salidas26[[CODIGO ]],LG26V[[#This Row],[CODIGO ]],salidas26[CANT BARRAS]) -> 0 | O17: =(LG26V[[#This Row],["J"PRECIO COMPRA ]]*LG26V[[#This Row],[STOCK JUEGOS]]) -> 2340 | P17: =(LG26V[[#This Row],["J" PRECIO VENTA ]]*LG26V[[#This Row],[STOCK JUEGOS]]) -> 3240 | Q17: =(LG26V[[#This Row],["B"PRECIO COMPRA]]*LG26V[[#This Row],[STOCK BARRAS]]) -> 0 | R17: =(LG26V[[#This Row],["B"PRECIO VENTA ]]*LG26V[[#This Row],[STOCK BARRAS]]) -> 0 | S17: 24 | U17: 5.4 | W17: XLM-0250/0251
A18: 15 | B18: 1036 | C18: 42LA6130-42LN5400 10B/3V | D18: =(LG26V[[#This Row],[CANTIDAD INICIAL JUEGO ]]+LG26V[[#This Row],[ENTRADAS JUEGOS ]]-LG26V[[#This Row],[SALIDAS JUEGOS]]) -> 17 | E18: =(LG26V[[#This Row],[CANTIDAD INICIAL BARRAS]]+LG26V[[#This Row],[ENTRADAS BARRAS]]-LG26V[[#This Row],[SALIDA BARRAS]]) -> 6 | F18: 180 | G18: 96.9 | H18: 10 | I18: =(LG26V[[#This Row],["J" PRECIO VENTA ]]/LG26V[[#This Row],[BARRAS]]) -> 18 | J18: =(LG26V[[#This Row],["J"PRECIO COMPRA ]]/LG26V[[#This Row],[BARRAS]]) -> 9.69 | K18: =SUMIF(entradas26[CODIGO],LG26V[[#This Row],[CODIGO ]],entradas26[[CAN JUEGOS ]]) -> 20 | L18: =SUMIF(entradas26[CODIGO],LG26V[[#This Row],[CODIGO ]],entradas26[CAN BARRAS]) -> 0 | M18: =SUMIF(salidas26[[CODIGO ]],LG26V[[#This Row],[CODIGO ]],salidas26[[CANT JUEGOS ]]) -> 14 | N18: =SUMIF(salidas26[[CODIGO ]],LG26V[[#This Row],[CODIGO ]],salidas26[CANT BARRAS]) -> 0 | O18: =(LG26V[[#This Row],["J"PRECIO COMPRA ]]*LG26V[[#This Row],[STOCK JUEGOS]]) -> 1647.3 | P18: =(LG26V[[#This Row],["J" PRECIO VENTA ]]*LG26V[[#This Row],[STOCK JUEGOS]]) -> 3060 | Q18: =(LG26V[[#This Row],["B"PRECIO COMPRA]]*LG26V[[#This Row],[STOCK BARRAS]]) -> 58.14 | R18: =(LG26V[[#This Row],["B"PRECIO VENTA ]]*LG26V[[#This Row],[STOCK BARRAS]]) -> 108 | S18: 11 | T18: 6 | U18: 5.1 | W18: XLM-0244/0242/0245/0243
A19: 16 | B19: 1039 | C19: 42LN5200/10B/3V | D19: =(LG26V[[#This Row],[CANTIDAD INICIAL JUEGO ]]+LG26V[[#This Row],[ENTRADAS JUEGOS ]]-LG26V[[#This Row],[SALIDAS JUEGOS]]) -> 15 | E19: =(LG26V[[#This Row],[CANTIDAD INICIAL BARRAS]]+LG26V[[#This Row],[ENTRADAS BARRAS]]-LG26V[[#This Row],[SALIDA BARRAS]]) -> 16 | F19: 200 | G19: 105 | H19: 10 | I19: =(LG26V[[#This Row],["J" PRECIO VENTA ]]/LG26V[[#This Row],[BARRAS]]) -> 20 | J19: =(LG26V[[#This Row],["J"PRECIO COMPRA ]]/LG26V[[#This Row],[BARRAS]]) -> 10.5 | K19: =SUMIF(entradas26[CODIGO],LG26V[[#This Row],[CODIGO ]],entradas26[[CAN JUEGOS ]]) -> 0 | L19: =SUMIF(entradas26[CODIGO],LG26V[[#This Row],[CODIGO ]],entradas26[CAN BARRAS]) -> 0 | M19: =SUMIF(salidas26[[CODIGO ]],LG26V[[#This Row],[CODIGO ]],salidas26[[CANT JUEGOS ]]) -> 2 | N19: =SUMIF(salidas26[[CODIGO ]],LG26V[[#This Row],[CODIGO ]],salidas26[CANT BARRAS]) -> 0 | O19: =(LG26V[[#This Row],["J"PRECIO COMPRA ]]*LG26V[[#This Row],[STOCK JUEGOS]]) -> 1575 | P19: =(LG26V[[#This Row],["J" PRECIO VENTA ]]*LG26V[[#This Row],[STOCK JUEGOS]]) -> 3000 | Q19: =(LG26V[[#This Row],["B"PRECIO COMPRA]]*LG26V[[#This Row],[STOCK BARRAS]]) -> 168 | R19: =(LG26V[[#This Row],["B"PRECIO VENTA ]]*LG26V[[#This Row],[STOCK BARRAS]]) -> 320 | S19: 17 | T19: 16 | U19: 5.64 | W19: XY-014
A20: 17 | B20: 1042 | C20: 42LS3450/10B | D20: =(LG26V[[#This Row],[CANTIDAD INICIAL JUEGO ]]+LG26V[[#This Row],[ENTRADAS JUEGOS ]]-LG26V[[#This Row],[SALIDAS JUEGOS]]) -> 6 | E20: =(LG26V[[#This Row],[CANTIDAD INICIAL BARRAS]]+LG26V[[#This Row],[ENTRADAS BARRAS]]-LG26V[[#This Row],[SALIDA BARRAS]]) -> 2 | F20: 250 | G20: 245 | H20: 10 | I20: =(LG26V[[#This Row],["J" PRECIO VENTA ]]/LG26V[[#This Row],[BARRAS]]) -> 25 | J20: =(LG26V[[#This Row],["J"PRECIO COMPRA ]]/LG26V[[#This Row],[BARRAS]]) -> 24.5 | K20: =SUMIF(entradas26[CODIGO],LG26V[[#This Row],[CODIGO ]],entradas26[[CAN JUEGOS ]]) -> 0 | L20: =SUMIF(entradas26[CODIGO],LG26V[[#This Row],[CODIGO ]],entradas26[CAN BARRAS]) -> 10 | M20: =SUMIF(salidas26[[CODIGO ]],LG26V[[#This Row],[CODIGO ]],salidas26[[CANT JUEGOS ]]) -> 2 | N20: =SUMIF(salidas26[[CODIGO ]],LG26V[[#This Row],[CODIGO ]],salidas26[CANT BARRAS]) -> 8 | O20: =(LG26V[[#This Row],["J"PRECIO COMPRA ]]*LG26V[[#This Row],[STOCK JUEGOS]]) -> 1470 | P20: =(LG26V[[#This Row],["J" PRECIO VENTA ]]*LG26V[[#This Row],[STOCK JUEGOS]]) -> 1500 | Q20: =(LG26V[[#This Row],["B"PRECIO COMPRA]]*LG26V[[#This Row],[STOCK BARRAS]]) -> 49 | R20: =(LG26V[[#This Row],["B"PRECIO VENTA ]]*LG26V[[#This Row],[STOCK BARRAS]]) -> 50 | S20: 8 | U20: 7.85 | W20: XLM-1232/1233
A21: 18 | B21: 1045 | C21: 42LM6200/1B | D21: =(LG26V[[#This Row],[CANTIDAD INICIAL JUEGO ]]+LG26V[[#This Row],[ENTRADAS JUEGOS ]]-LG26V[[#This Row],[SALIDAS JUEGOS]]) -> 12 | E21: =(LG26V[[#This Row],[CANTIDAD INICIAL BARRAS]]+LG26V[[#This Row],[ENTRADAS BARRAS]]-LG26V[[#This Row],[SALIDA BARRAS]]) -> 0 | F21: 140 | G21: 30 | H21: 1 | I21: =(LG26V[[#This Row],["J" PRECIO VENTA ]]/LG26V[[#This Row],[BARRAS]]) -> 140 | J21: =(LG26V[[#This Row],["J"PRECIO COMPRA ]]/LG26V[[#This Row],[BARRAS]]) -> 30 | K21: =SUMIF(entradas26[CODIGO],LG26V[[#This Row],[CODIGO ]],entradas26[[CAN JUEGOS ]]) -> 0 | L21: =SUMIF(entradas26[CODIGO],LG26V[[#This Row],[CODIGO ]],entradas26[CAN BARRAS]) -> 0 | M21: =SUMIF(salidas26[[CODIGO ]],LG26V[[#This Row],[CODIGO ]],salidas26[[CANT JUEGOS ]]) -> 1 | N21: =SUMIF(salidas26[[CODIGO ]],LG26V[[#This Row],[CODIGO ]],salidas26[CANT BARRAS]) -> 0 | O21: =(LG26V[[#This Row],["J"PRECIO COMPRA ]]*LG26V[[#This Row],[STOCK JUEGOS]]) -> 360 | P21: =(LG26V[[#This Row],["J" PRECIO VENTA ]]*LG26V[[#This Row],[STOCK JUEGOS]]) -> 1680 | Q21: =(LG26V[[#This Row],["B"PRECIO COMPRA]]*LG26V[[#This Row],[STOCK BARRAS]]) -> 0 | R21: =(LG26V[[#This Row],["B"PRECIO VENTA ]]*LG26V[[#This Row],[STOCK BARRAS]]) -> 0 | S21: 13 | U21: 2.15 | W21: XM2746.1
A22: 19 | B22: 1048 | C22: 43 LJ5000 /10L/3V/5B | D22: =(LG26V[[#This Row],[CANTIDAD INICIAL JUEGO ]]+LG26V[[#This Row],[ENTRADAS JUEGOS ]]-LG26V[[#This Row],[SALIDAS JUEGOS]]) -> 0 | E22: =(LG26V[[#This Row],[CANTIDAD INICIAL BARRAS]]+LG26V[[#This Row],[ENTRADAS BARRAS]]-LG26V[[#This Row],[SALIDA BARRAS]]) -> 3 | F22: 180 | G22: 150 | H22: 5 | I22: =(LG26V[[#This Row],["J" PRECIO VENTA ]]/LG26V[[#This Row],[BARRAS]]) -> 36 | J22: =(LG26V[[#This Row],["J"PRECIO COMPRA ]]/LG26V[[#This Row],[BARRAS]]) -> 30 | K22: =SUMIF(entradas26[CODIGO],LG26V[[#This Row],[CODIGO ]],entradas26[[CAN JUEGOS ]]) -> 0 | L22: =SUMIF(entradas26[CODIGO],LG26V[[#This Row],[CODIGO ]],entradas26[CAN BARRAS]) -> 0 | M22: =SUMIF(salidas26[[CODIGO ]],LG26V[[#This Row],[CODIGO ]],salidas26[[CANT JUEGOS ]]) -> 0 | N22: =SUMIF(salidas26[[CODIGO ]],LG26V[[#This Row],[CODIGO ]],salidas26[CANT BARRAS]) -> 0 | O22: =(LG26V[[#This Row],["J"PRECIO COMPRA ]]*LG26V[[#This Row],[STOCK JUEGOS]]) -> 0 | P22: =(LG26V[[#This Row],["J" PRECIO VENTA ]]*LG26V[[#This Row],[STOCK JUEGOS]]) -> 0 | Q22: =(LG26V[[#This Row],["B"PRECIO COMPRA]]*LG26V[[#This Row],[STOCK BARRAS]]) -> 90 | R22: =(LG26V[[#This Row],["B"PRECIO VENTA ]]*LG26V[[#This Row],[STOCK BARRAS]]) -> 108 | T22: 3
A23: 20 | B23: 1049 | C23: 43LJ5500 3B/7L | D23: =(LG26V[[#This Row],[CANTIDAD INICIAL JUEGO ]]+LG26V[[#This Row],[ENTRADAS JUEGOS ]]-LG26V[[#This Row],[SALIDAS JUEGOS]]) -> 24 | E23: =(LG26V[[#This Row],[CANTIDAD INICIAL BARRAS]]+LG26V[[#This Row],[ENTRADAS BARRAS]]-LG26V[[#This Row],[SALIDA BARRAS]]) -> 0 | F23: 180 | G23: 65 | H23: 3 | I23: =(LG26V[[#This Row],["J" PRECIO VENTA ]]/LG26V[[#This Row],[BARRAS]]) -> 60 | J23: =(LG26V[[#This Row],["J"PRECIO COMPRA ]]/LG26V[[#This Row],[BARRAS]]) -> 21.666667 | K23: =SUMIF(entradas26[CODIGO],LG26V[[#This Row],[CODIGO ]],entradas26[[CAN JUEGOS ]]) -> 20 | L23: =SUMIF(entradas26[CODIGO],LG26V[[#This Row],[CODIGO ]],entradas26[CAN BARRAS]) -> 0 | M23: =SUMIF(salidas26[[CODIGO ]],LG26V[[#This Row],[CODIGO ]],salidas26[[CANT JUEGOS ]]) -> 6 | N23: =SUMIF(salidas26[[CODIGO ]],LG26V[[#This Row],[CODIGO ]],salidas26[CANT BARRAS]) -> 0 | O23: =(LG26V[[#This Row],["J"PRECIO COMPRA ]]*LG26V[[#This Row],[STOCK JUEGOS]]) -> 1560 | P23: =(LG26V[[#This Row],["J" PRECIO VENTA ]]*LG26V[[#This Row],[STOCK JUEGOS]]) -> 4320 | Q23: =(LG26V[[#This Row],["B"PRECIO COMPRA]]*LG26V[[#This Row],[STOCK BARRAS]]) -> 0 | R23: =(LG26V[[#This Row],["B"PRECIO VENTA ]]*LG26V[[#This Row],[STOCK BARRAS]]) -> 0 | S23: 10 | U23: 3 | W23: XLM-0354
A24: 21 | B24: 1057 | C24: 43UJ6560-LUPA GIGANTE/4B | D24: =(LG26V[[#This Row],[CANTIDAD INICIAL JUEGO ]]+LG26V[[#This Row],[ENTRADAS JUEGOS ]]-LG26V[[#This Row],[SALIDAS JUEGOS]]) -> 1 | E24: =(LG26V[[#This Row],[CANTIDAD INICIAL BARRAS]]+LG26V[[#This Row],[ENTRADAS BARRAS]]-LG26V[[#This Row],[SALIDA BARRAS]]) -> 0 | F24: 180 | G24: 100 | H24: 4 | I24: =(LG26V[[#This Row],["J" PRECIO VENTA ]]/LG26V[[#This Row],[BARRAS]]) -> 45 | J24: =(LG26V[[#This Row],["J"PRECIO COMPRA ]]/LG26V[[#This Row],[BARRAS]]) -> 25 | K24: =SUMIF(entradas26[CODIGO],LG26V[[#This Row],[CODIGO ]],entradas26[[CAN JUEGOS ]]) -> 0 | L24: =SUMIF(entradas26[CODIGO],LG26V[[#This Row],[CODIGO ]],entradas26[CAN BARRAS]) -> 0 | M24: =SUMIF(salidas26[[CODIGO ]],LG26V[[#This Row],[CODIGO ]],salidas26[[CANT JUEGOS ]]) -> 0 | N24: =SUMIF(salidas26[[CODIGO ]],LG26V[[#This Row],[CODIGO ]],salidas26[CANT BARRAS]) -> 0 | O24: =(LG26V[[#This Row],["J"PRECIO COMPRA ]]*LG26V[[#This Row],[STOCK JUEGOS]]) -> 100 | P24: =(LG26V[[#This Row],["J" PRECIO VENTA ]]*LG26V[[#This Row],[STOCK JUEGOS]]) -> 180 | Q24: =(LG26V[[#This Row],["B"PRECIO COMPRA]]*LG26V[[#This Row],[STOCK BARRAS]]) -> 0 | R24: =(LG26V[[#This Row],["B"PRECIO VENTA ]]*LG26V[[#This Row],[STOCK BARRAS]]) -> 0 | S24: 1
A25: 22 | B25: 1060 | C25: 43LH-LF 5100/6B | D25: =(LG26V[[#This Row],[CANTIDAD INICIAL JUEGO ]]+LG26V[[#This Row],[ENTRADAS JUEGOS ]]-LG26V[[#This Row],[SALIDAS JUEGOS]]) -> 13 | E25: =(LG26V[[#This Row],[CANTIDAD INICIAL BARRAS]]+LG26V[[#This Row],[ENTRADAS BARRAS]]-LG26V[[#This Row],[SALIDA BARRAS]]) -> 4 | F25: 180 | G25: 85 | H25: 6 | I25: =(LG26V[[#This Row],["J" PRECIO VENTA ]]/LG26V[[#This Row],[BARRAS]]) -> 30 | J25: =(LG26V[[#This Row],["J"PRECIO COMPRA ]]/LG26V[[#This Row],[BARRAS]]) -> 14.166667 | K25: =SUMIF(entradas26[CODIGO],LG26V[[#This Row],[CODIGO ]],entradas26[[CAN JUEGOS ]]) -> 0 | L25: =SUMIF(entradas26[CODIGO],LG26V[[#This Row],[CODIGO ]],entradas26[CAN BARRAS]) -> 0 | M25: =SUMIF(salidas26[[CODIGO ]],LG26V[[#This Row],[CODIGO ]],salidas26[[CANT JUEGOS ]]) -> 3 | N25: =SUMIF(salidas26[[CODIGO ]],LG26V[[#This Row],[CODIGO ]],salidas26[CANT BARRAS]) -> 0 | O25: =(LG26V[[#This Row],["J"PRECIO COMPRA ]]*LG26V[[#This Row],[STOCK JUEGOS]]) -> 1105 | P25: =(LG26V[[#This Row],["J" PRECIO VENTA ]]*LG26V[[#This Row],[STOCK JUEGOS]]) -> 2340 | Q25: =(LG26V[[#This Row],["B"PRECIO COMPRA]]*LG26V[[#This Row],[STOCK BARRAS]]) -> 56.666667 | R25: =(LG26V[[#This Row],["B"PRECIO VENTA ]]*LG26V[[#This Row],[STOCK BARRAS]]) -> 120 | S25: 16 | T25: 4 | U25: 3.3 | W25: XLM-0545-0544
A26: 23 | B26: 1063 | C26: 43LH5000/5B | D26: =(LG26V[[#This Row],[CANTIDAD INICIAL JUEGO ]]+LG26V[[#This Row],[ENTRADAS JUEGOS ]]-LG26V[[#This Row],[SALIDAS JUEGOS]]) -> 19 | E26: =(LG26V[[#This Row],[CANTIDAD INICIAL BARRAS]]+LG26V[[#This Row],[ENTRADAS BARRAS]]-LG26V[[#This Row],[SALIDA BARRAS]]) -> 2 | F26: 180 | G26: 82 | H26: 5 | I26: =(LG26V[[#This Row],["J" PRECIO VENTA ]]/LG26V[[#This Row],[BARRAS]]) -> 36 | J26: =(LG26V[[#This Row],["J"PRECIO COMPRA ]]/LG26V[[#This Row],[BARRAS]]) -> 16.4 | K26: =SUMIF(entradas26[CODIGO],LG26V[[#This Row],[CODIGO ]],entradas26[[CAN JUEGOS ]]) -> 0 | L26: =SUMIF(entradas26[CODIGO],LG26V[[#This Row],[CODIGO ]],entradas26[CAN BARRAS]) -> 0 | M26: =SUMIF(salidas26[[CODIGO ]],LG26V[[#This Row],[CODIGO ]],salidas26[[CANT JUEGOS ]]) -> 4 | N26: =SUMIF(salidas26[[CODIGO ]],LG26V[[#This Row],[CODIGO ]],salidas26[CANT BARRAS]) -> 0 | O26: =(LG26V[[#This Row],["J"PRECIO COMPRA ]]*LG26V[[#This Row],[STOCK JUEGOS]]) -> 1558 | P26: =(LG26V[[#This Row],["J" PRECIO VENTA ]]*LG26V[[#This Row],[STOCK JUEGOS]]) -> 3420 | Q26: =(LG26V[[#This Row],["B"PRECIO COMPRA]]*LG26V[[#This Row],[STOCK BARRAS]]) -> 32.8 | R26: =(LG26V[[#This Row],["B"PRECIO VENTA ]]*LG26V[[#This Row],[STOCK BARRAS]]) -> 72 | S26: 23 | T26: 2 | U26: 3.55 | W26: XLM-0735
A27: 24 | B27: 1064 | C27: 43LK540 8B/3V | D27: =(LG26V[[#This Row],[CANTIDAD INICIAL JUEGO ]]+LG26V[[#This Row],[ENTRADAS JUEGOS ]]-LG26V[[#This Row],[SALIDAS JUEGOS]]) -> 18 | E27: =(LG26V[[#This Row],[CANTIDAD INICIAL BARRAS]]+LG26V[[#This Row],[ENTRADAS BARRAS]]-LG26V[[#This Row],[SALIDA BARRAS]]) -> 0 | F27: 180 | G27: 104 | H27: 8 | I27: =(LG26V[[#This Row],["J" PRECIO VENTA ]]/LG26V[[#This Row],[BARRAS]]) -> 22.5 | J27: =(LG26V[[#This Row],["J"PRECIO COMPRA ]]/LG26V[[#This Row],[BARRAS]]) -> 13 | K27: =SUMIF(entradas26[CODIGO],LG26V[[#This Row],[CODIGO ]],entradas26[[CAN JUEGOS ]]) -> 0 | L27: =SUMIF(entradas26[CODIGO],LG26V[[#This Row],[CODIGO ]],entradas26[CAN BARRAS]) -> 0 | M27: =SUMIF(salidas26[[CODIGO ]],LG26V[[#This Row],[CODIGO ]],salidas26[[CANT JUEGOS ]]) -> 2 | N27: =SUMIF(salidas26[[CODIGO ]],LG26V[[#This Row],[CODIGO ]],salidas26[CANT BARRAS]) -> 0 | O27: =(LG26V[[#This Row],["J"PRECIO COMPRA ]]*LG26V[[#This Row],[STOCK JUEGOS]]) -> 1872 | P27: =(LG26V[[#This Row],["J" PRECIO VENTA ]]*LG26V[[#This Row],[STOCK JUEGOS]]) -> 3240 | Q27: =(LG26V[[#This Row],["B"PRECIO COMPRA]]*LG26V[[#This Row],[STOCK BARRAS]]) -> 0 | R27: =(LG26V[[#This Row],["B"PRECIO VENTA ]]*LG26V[[#This Row],[STOCK BARRAS]]) -> 0 | S27: 20 | U27: 4.5 | W27: XY-0730
B28: 1065 | C28: 43UM7300 | D28: =(LG26V[[#This Row],[CANTIDAD INICIAL JUEGO ]]+LG26V[[#This Row],[ENTRADAS JUEGOS ]]-LG26V[[#This Row],[SALIDAS JUEGOS]]) -> 20 | E28: =(LG26V[[#This Row],[CANTIDAD INICIAL BARRAS]]+LG26V[[#This Row],[ENTRADAS BARRAS]]-LG26V[[#This Row],[SALIDA BARRAS]]) -> 0 | F28: 180 | G28: 80 | I28: =(LG26V[[#This Row],["J" PRECIO VENTA ]]/LG26V[[#This Row],[BARRAS]]) -> #DIV/0! | J28: =(LG26V[[#This Row],["J"PRECIO COMPRA ]]/LG26V[[#This Row],[BARRAS]]) -> #DIV/0! | K28: =SUMIF(entradas26[CODIGO],LG26V[[#This Row],[CODIGO ]],entradas26[[CAN JUEGOS ]]) -> 20 | L28: =SUMIF(entradas26[CODIGO],LG26V[[#This Row],[CODIGO ]],entradas26[CAN BARRAS]) -> 0 | M28: =SUMIF(salidas26[[CODIGO ]],LG26V[[#This Row],[CODIGO ]],salidas26[[CANT JUEGOS ]]) -> 0 | N28: =SUMIF(salidas26[[CODIGO ]],LG26V[[#This Row],[CODIGO ]],salidas26[CANT BARRAS]) -> 0 | O28: =(LG26V[[#This Row],["J"PRECIO COMPRA ]]*LG26V[[#This Row],[STOCK JUEGOS]]) -> 1600 | P28: =(LG26V[[#This Row],["J" PRECIO VENTA ]]*LG26V[[#This Row],[STOCK JUEGOS]]) -> 3600 | Q28: =(LG26V[[#This Row],["B"PRECIO COMPRA]]*LG26V[[#This Row],[STOCK BARRAS]]) -> #DIV/0! | R28: =(LG26V[[#This Row],["B"PRECIO VENTA ]]*LG26V[[#This Row],[STOCK BARRAS]]) -> #DIV/0! | U28: 4.2 | W28: XLM-1608
A29: 25 | B29: 1066 | C29: 47LA6130-12B/3V | D29: =(LG26V[[#This Row],[CANTIDAD INICIAL JUEGO ]]+LG26V[[#This Row],[ENTRADAS JUEGOS ]]-LG26V[[#This Row],[SALIDAS JUEGOS]]) -> 8 | E29: =(LG26V[[#This Row],[CANTIDAD INICIAL BARRAS]]+LG26V[[#This Row],[ENTRADAS BARRAS]]-LG26V[[#This Row],[SALIDA BARRAS]]) -> 11 | F29: 240 | G29: 138 | H29: 12 | I29: =(LG26V[[#This Row],["J" PRECIO VENTA ]]/LG26V[[#This Row],[BARRAS]]) -> 20 | J29: =(LG26V[[#This Row],["J"PRECIO COMPRA ]]/LG26V[[#This Row],[BARRAS]]) -> 11.5 | K29: =SUMIF(entradas26[CODIGO],LG26V[[#This Row],[CODIGO ]],entradas26[[CAN JUEGOS ]]) -> 0 | L29: =SUMIF(entradas26[CODIGO],LG26V[[#This Row],[CODIGO ]],entradas26[CAN BARRAS]) -> 0 | M29: =SUMIF(salidas26[[CODIGO ]],LG26V[[#This Row],[CODIGO ]],salidas26[[CANT JUEGOS ]]) -> 3 | N29: =SUMIF(salidas26[[CODIGO ]],LG26V[[#This Row],[CODIGO ]],salidas26[CANT BARRAS]) -> 0 | O29: =(LG26V[[#This Row],["J"PRECIO COMPRA ]]*LG26V[[#This Row],[STOCK JUEGOS]]) -> 1104 | P29: =(LG26V[[#This Row],["J" PRECIO VENTA ]]*LG26V[[#This Row],[STOCK JUEGOS]]) -> 1920 | Q29: =(LG26V[[#This Row],["B"PRECIO COMPRA]]*LG26V[[#This Row],[STOCK BARRAS]]) -> 126.5 | R29: =(LG26V[[#This Row],["B"PRECIO VENTA ]]*LG26V[[#This Row],[STOCK BARRAS]]) -> 220 | S29: 11 | T29: 11 | U29: 4.6 | W29: XLM-0271-0272-0273-0274
A30: 26 | B30: 1067 | C30: 47LA6600/2B | D30: =(LG26V[[#This Row],[CANTIDAD INICIAL JUEGO ]]+LG26V[[#This Row],[ENTRADAS JUEGOS ]]-LG26V[[#This Row],[SALIDAS JUEGOS]]) -> 20 | E30: =(LG26V[[#This Row],[CANTIDAD INICIAL BARRAS]]+LG26V[[#This Row],[ENTRADAS BARRAS]]-LG26V[[#This Row],[SALIDA BARRAS]]) -> 0 | F30: 250 | G30: 150 | H30: 2 | I30: =(LG26V[[#This Row],["J" PRECIO VENTA ]]/LG26V[[#This Row],[BARRAS]]) -> 125 | J30: =(LG26V[[#This Row],["J"PRECIO COMPRA ]]/LG26V[[#This Row],[BARRAS]]) -> 75 | K30: =SUMIF(entradas26[CODIGO],LG26V[[#This Row],[CODIGO ]],entradas26[[CAN JUEGOS ]]) -> 20 | L30: =SUMIF(entradas26[CODIGO],LG26V[[#This Row],[CODIGO ]],entradas26[CAN BARRAS]) -> 0 | M30: =SUMIF(salidas26[[CODIGO ]],LG26V[[#This Row],[CODIGO ]],salidas26[[CANT JUEGOS ]]) -> 2 | N30: =SUMIF(salidas26[[CODIGO ]],LG26V[[#This Row],[CODIGO ]],salidas26[CANT BARRAS]) -> 0 | O30: =(LG26V[[#This Row],["J"PRECIO COMPRA ]]*LG26V[[#This Row],[STOCK JUEGOS]]) -> 3000 | P30: =(LG26V[[#This Row],["J" PRECIO VENTA ]]*LG26V[[#This Row],[STOCK JUEGOS]]) -> 5000 | Q30: =(LG26V[[#This Row],["B"PRECIO COMPRA]]*LG26V[[#This Row],[STOCK BARRAS]]) -> 0 | R30: =(LG26V[[#This Row],["B"PRECIO VENTA ]]*LG26V[[#This Row],[STOCK BARRAS]]) -> 0 | S30: 2 | U30: 4.6 | W30: XLM- 1296/1297
A31: 27 | B31: 1069 | C31: 47LB6500- 8B/6V | D31: =(LG26V[[#This Row],[CANTIDAD INICIAL JUEGO ]]+LG26V[[#This Row],[ENTRADAS JUEGOS ]]-LG26V[[#This Row],[SALIDAS JUEGOS]]) -> 10 | E31: =(LG26V[[#This Row],[CANTIDAD INICIAL BARRAS]]+LG26V[[#This Row],[ENTRADAS BARRAS]]-LG26V[[#This Row],[SALIDA BARRAS]]) -> 11 | F31: 250 | G31: 88 | H31: 8 | I31: =(LG26V[[#This Row],["J" PRECIO VENTA ]]/LG26V[[#This Row],[BARRAS]]) -> 31.25 | J31: =(LG26V[[#This Row],["J"PRECIO COMPRA ]]/LG26V[[#This Row],[BARRAS]]) -> 11 | K31: =SUMIF(entradas26[CODIGO],LG26V[[#This Row],[CODIGO ]],entradas26[[CAN JUEGOS ]]) -> 0 | L31: =SUMIF(entradas26[CODIGO],LG26V[[#This Row],[CODIGO ]],entradas26[CAN BARRAS]) -> 0 | M31: =SUMIF(salidas26[[CODIGO ]],LG26V[[#This Row],[CODIGO ]],salidas26[[CANT JUEGOS ]]) -> 11 | N31: =SUMIF(salidas26[[CODIGO ]],LG26V[[#This Row],[CODIGO ]],salidas26[CANT BARRAS]) -> 0 | O31: =(LG26V[[#This Row],["J"PRECIO COMPRA ]]*LG26V[[#This Row],[STOCK JUEGOS]]) -> 880 | P31: =(LG26V[[#This Row],["J" PRECIO VENTA ]]*LG26V[[#This Row],[STOCK JUEGOS]]) -> 2500 | Q31: =(LG26V[[#This Row],["B"PRECIO COMPRA]]*LG26V[[#This Row],[STOCK BARRAS]]) -> 121 | R31: =(LG26V[[#This Row],["B"PRECIO VENTA ]]*LG26V[[#This Row],[STOCK BARRAS]]) -> 343.75 | S31: 21 | T31: 11 | U31: 5.9 | W31: XLM-0265/0266
A32: 28 | B32: 1072 | C32: 47LM6200/2B | D32: =(LG26V[[#This Row],[CANTIDAD INICIAL JUEGO ]]+LG26V[[#This Row],[ENTRADAS JUEGOS ]]-LG26V[[#This Row],[SALIDAS JUEGOS]]) -> 18 | E32: =(LG26V[[#This Row],[CANTIDAD INICIAL BARRAS]]+LG26V[[#This Row],[ENTRADAS BARRAS]]-LG26V[[#This Row],[SALIDA BARRAS]]) -> 0 | F32: 200 | G32: 103 | H32: 2 | I32: =(LG26V[[#This Row],["J" PRECIO VENTA ]]/LG26V[[#This Row],[BARRAS]]) -> 100 | J32: =(LG26V[[#This Row],["J"PRECIO COMPRA ]]/LG26V[[#This Row],[BARRAS]]) -> 51.5 | K32: =SUMIF(entradas26[CODIGO],LG26V[[#This Row],[CODIGO ]],entradas26[[CAN JUEGOS ]]) -> 0 | L32: =SUMIF(entradas26[CODIGO],LG26V[[#This Row],[CODIGO ]],entradas26[CAN BARRAS]) -> 0 | M32: =SUMIF(salidas26[[CODIGO ]],LG26V[[#This Row],[CODIGO ]],salidas26[[CANT JUEGOS ]]) -> 0 | N32: =SUMIF(salidas26[[CODIGO ]],LG26V[[#This Row],[CODIGO ]],salidas26[CANT BARRAS]) -> 0 | O32: =(LG26V[[#This Row],["J"PRECIO COMPRA ]]*LG26V[[#This Row],[STOCK JUEGOS]]) -> 1854 | P32: =(LG26V[[#This Row],["J" PRECIO VENTA ]]*LG26V[[#This Row],[STOCK JUEGOS]]) -> 3600 | Q32: =(LG26V[[#This Row],["B"PRECIO COMPRA]]*LG26V[[#This Row],[STOCK BARRAS]]) -> 0 | R32: =(LG26V[[#This Row],["B"PRECIO VENTA ]]*LG26V[[#This Row],[STOCK BARRAS]]) -> 0 | S32: 18 | W32: XLM-0462/0463
A33: 29 | B33: 1073 | C33: 47 LWU6500/2B | D33: =(LG26V[[#This Row],[CANTIDAD INICIAL JUEGO ]]+LG26V[[#This Row],[ENTRADAS JUEGOS ]]-LG26V[[#This Row],[SALIDAS JUEGOS]]) -> 2 | E33: =(LG26V[[#This Row],[CANTIDAD INICIAL BARRAS]]+LG26V[[#This Row],[ENTRADAS BARRAS]]-LG26V[[#This Row],[SALIDA BARRAS]]) -> 0 | F33: 250 | G33: 135 | H33: 2 | I33: =(LG26V[[#This Row],["J" PRECIO VENTA ]]/LG26V[[#This Row],[BARRAS]]) -> 125 | J33: =(LG26V[[#This Row],["J"PRECIO COMPRA ]]/LG26V[[#This Row],[BARRAS]]) -> 67.5 | K33: =SUMIF(entradas26[CODIGO],LG26V[[#This Row],[CODIGO ]],entradas26[[CAN JUEGOS ]]) -> 0 | L33: =SUMIF(entradas26[CODIGO],LG26V[[#This Row],[CODIGO ]],entradas26[CAN BARRAS]) -> 0 | M33: =SUMIF(salidas26[[CODIGO ]],LG26V[[#This Row],[CODIGO ]],salidas26[[CANT JUEGOS ]]) -> 0 | N33: =SUMIF(salidas26[[CODIGO ]],LG26V[[#This Row],[CODIGO ]],salidas26[CANT BARRAS]) -> 0 | O33: =(LG26V[[#This Row],["J"PRECIO COMPRA ]]*LG26V[[#This Row],[STOCK JUEGOS]]) -> 270 | P33: =(LG26V[[#This Row],["J" PRECIO VENTA ]]*LG26V[[#This Row],[STOCK JUEGOS]]) -> 500 | Q33: =(LG26V[[#This Row],["B"PRECIO COMPRA]]*LG26V[[#This Row],[STOCK BARRAS]]) -> 0 | R33: =(LG26V[[#This Row],["B"PRECIO VENTA ]]*LG26V[[#This Row],[STOCK BARRAS]]) -> 0 | S33: 2
A34: 30 | B34: 1075 | C34: 49LJ5500-49UJ6300/8B | D34: =(LG26V[[#This Row],[CANTIDAD INICIAL JUEGO ]]+LG26V[[#This Row],[ENTRADAS JUEGOS ]]-LG26V[[#This Row],[SALIDAS JUEGOS]]) -> 22 | E34: =(LG26V[[#This Row],[CANTIDAD INICIAL BARRAS]]+LG26V[[#This Row],[ENTRADAS BARRAS]]-LG26V[[#This Row],[SALIDA BARRAS]]) -> 0 | F34: 240 | G34: 57 | H34: 8 | I34: =(LG26V[[#This Row],["J" PRECIO VENTA ]]/LG26V[[#This Row],[BARRAS]]) -> 30 | J34: =(LG26V[[#This Row],["J"PRECIO COMPRA ]]/LG26V[[#This Row],[BARRAS]]) -> 7.125 | K34: =SUMIF(entradas26[CODIGO],LG26V[[#This Row],[CODIGO ]],entradas26[[CAN JUEGOS ]]) -> 20 | L34: =SUMIF(entradas26[CODIGO],LG26V[[#This Row],[CODIGO ]],entradas26[CAN BARRAS]) -> 0 | M34: =SUMIF(salidas26[[CODIGO ]],LG26V[[#This Row],[CODIGO ]],salidas26[[CANT JUEGOS ]]) -> 4 | N34: =SUMIF(salidas26[[CODIGO ]],LG26V[[#This Row],[CODIGO ]],salidas26[CANT BARRAS]) -> 0 | O34: =(LG26V[[#This Row],["J"PRECIO COMPRA ]]*LG26V[[#This Row],[STOCK JUEGOS]]) -> 1254 | P34: =(LG26V[[#This Row],["J" PRECIO VENTA ]]*LG26V[[#This Row],[STOCK JUEGOS]]) -> 5280 | Q34: =(LG26V[[#This Row],["B"PRECIO COMPRA]]*LG26V[[#This Row],[STOCK BARRAS]]) -> 0 | R34: =(LG26V[[#This Row],["B"PRECIO VENTA ]]*LG26V[[#This Row],[STOCK BARRAS]]) -> 0 | S34: 6 | U34: 3 | W34: XLM-0806/0807
A35: 31 | B35: 1076 | C35: 49 UJ6500 /8B | D35: =(LG26V[[#This Row],[CANTIDAD INICIAL JUEGO ]]+LG26V[[#This Row],[ENTRADAS JUEGOS ]]-LG26V[[#This Row],[SALIDAS JUEGOS]]) -> 1 | E35: =(LG26V[[#This Row],[CANTIDAD INICIAL BARRAS]]+LG26V[[#This Row],[ENTRADAS BARRAS]]-LG26V[[#This Row],[SALIDA BARRAS]]) -> 0 | F35: 250 | G35: 200 | H35: 8 | I35: =(LG26V[[#This Row],["J" PRECIO VENTA ]]/LG26V[[#This Row],[BARRAS]]) -> 31.25 | J35: =(LG26V[[#This Row],["J"PRECIO COMPRA ]]/LG26V[[#This Row],[BARRAS]]) -> 25 | K35: =SUMIF(entradas26[CODIGO],LG26V[[#This Row],[CODIGO ]],entradas26[[CAN JUEGOS ]]) -> 0 | L35: =SUMIF(entradas26[CODIGO],LG26V[[#This Row],[CODIGO ]],entradas26[CAN BARRAS]) -> 0 | M35: =SUMIF(salidas26[[CODIGO ]],LG26V[[#This Row],[CODIGO ]],salidas26[[CANT JUEGOS ]]) -> 1 | N35: =SUMIF(salidas26[[CODIGO ]],LG26V[[#This Row],[CODIGO ]],salidas26[CANT BARRAS]) -> 0 | O35: =(LG26V[[#This Row],["J"PRECIO COMPRA ]]*LG26V[[#This Row],[STOCK JUEGOS]]) -> 200 | P35: =(LG26V[[#This Row],["J" PRECIO VENTA ]]*LG26V[[#This Row],[STOCK JUEGOS]]) -> 250 | Q35: =(LG26V[[#This Row],["B"PRECIO COMPRA]]*LG26V[[#This Row],[STOCK BARRAS]]) -> 0 | R35: =(LG26V[[#This Row],["B"PRECIO VENTA ]]*LG26V[[#This Row],[STOCK BARRAS]]) -> 0 | S35: 2
A36: 32 | B36: 1078 | C36: 49LB-LF/10B | D36: =(LG26V[[#This Row],[CANTIDAD INICIAL JUEGO ]]+LG26V[[#This Row],[ENTRADAS JUEGOS ]]-LG26V[[#This Row],[SALIDAS JUEGOS]]) -> 6 | E36: =(LG26V[[#This Row],[CANTIDAD INICIAL BARRAS]]+LG26V[[#This Row],[ENTRADAS BARRAS]]-LG26V[[#This Row],[SALIDA BARRAS]]) -> 9 | F36: 280 | G36: 183 | H36: 10 | I36: =(LG26V[[#This Row],["J" PRECIO VENTA ]]/LG26V[[#This Row],[BARRAS]]) -> 28 | J36: =(LG26V[[#This Row],["J"PRECIO COMPRA ]]/LG26V[[#This Row],[BARRAS]]) -> 18.3 | K36: =SUMIF(entradas26[CODIGO],LG26V[[#This Row],[CODIGO ]],entradas26[[CAN JUEGOS ]]) -> 0 | L36: =SUMIF(entradas26[CODIGO],LG26V[[#This Row],[CODIGO ]],entradas26[CAN BARRAS]) -> 0 | M36: =SUMIF(salidas26[[CODIGO ]],LG26V[[#This Row],[CODIGO ]],salidas26[[CANT JUEGOS ]]) -> 8 | N36: =SUMIF(salidas26[[CODIGO ]],LG26V[[#This Row],[CODIGO ]],salidas26[CANT BARRAS]) -> 0 | O36: =(LG26V[[#This Row],["J"PRECIO COMPRA ]]*LG26V[[#This Row],[STOCK JUEGOS]]) -> 1098 | P36: =(LG26V[[#This Row],["J" PRECIO VENTA ]]*LG26V[[#This Row],[STOCK JUEGOS]]) -> 1680 | Q36: =(LG26V[[#This Row],["B"PRECIO COMPRA]]*LG26V[[#This Row],[STOCK BARRAS]]) -> 164.7 | R36: =(LG26V[[#This Row],["B"PRECIO VENTA ]]*LG26V[[#This Row],[STOCK BARRAS]]) -> 252 | S36: 14 | T36: 9 | U36: 6.15 | W36: XLM-0279/0280
A37: 33 | B37: 1081 | C37: 49LF5400 2B EL JUEGO | D37: =(LG26V[[#This Row],[CANTIDAD INICIAL JUEGO ]]+LG26V[[#This Row],[ENTRADAS JUEGOS ]]-LG26V[[#This Row],[SALIDAS JUEGOS]]) -> 2 | E37: =(LG26V[[#This Row],[CANTIDAD INICIAL BARRAS]]+LG26V[[#This Row],[ENTRADAS BARRAS]]-LG26V[[#This Row],[SALIDA BARRAS]]) -> 0 | F37: 200 | G37: 120 | H37: 2 | I37: =(LG26V[[#This Row],["J" PRECIO VENTA ]]/LG26V[[#This Row],[BARRAS]]) -> 100 | J37: =(LG26V[[#This Row],["J"PRECIO COMPRA ]]/LG26V[[#This Row],[BARRAS]]) -> 60 | K37: =SUMIF(entradas26[CODIGO],LG26V[[#This Row],[CODIGO ]],entradas26[[CAN JUEGOS ]]) -> 0 | L37: =SUMIF(entradas26[CODIGO],LG26V[[#This Row],[CODIGO ]],entradas26[CAN BARRAS]) -> 0 | M37: =SUMIF(salidas26[[CODIGO ]],LG26V[[#This Row],[CODIGO ]],salidas26[[CANT JUEGOS ]]) -> 2 | N37: =SUMIF(salidas26[[CODIGO ]],LG26V[[#This Row],[CODIGO ]],salidas26[CANT BARRAS]) -> 0 | O37: =(LG26V[[#This Row],["J"PRECIO COMPRA ]]*LG26V[[#This Row],[STOCK JUEGOS]]) -> 240 | P37: =(LG26V[[#This Row],["J" PRECIO VENTA ]]*LG26V[[#This Row],[STOCK JUEGOS]]) -> 400 | Q37: =(LG26V[[#This Row],["B"PRECIO COMPRA]]*LG26V[[#This Row],[STOCK BARRAS]]) -> 0 | R37: =(LG26V[[#This Row],["B"PRECIO VENTA ]]*LG26V[[#This Row],[STOCK BARRAS]]) -> 0 | S37: 4
A38: 34 | B38: 1084 | C38: 49LJ5100/8B | D38: =(LG26V[[#This Row],[CANTIDAD INICIAL JUEGO ]]+LG26V[[#This Row],[ENTRADAS JUEGOS ]]-LG26V[[#This Row],[SALIDAS JUEGOS]]) -> 0 | E38: =(LG26V[[#This Row],[CANTIDAD INICIAL BARRAS]]+LG26V[[#This Row],[ENTRADAS BARRAS]]-LG26V[[#This Row],[SALIDA BARRAS]]) -> 6 | F38: 250 | G38: 120 | H38: 8 | I38: =(LG26V[[#This Row],["J" PRECIO VENTA ]]/LG26V[[#This Row],[BARRAS]]) -> 31.25 | J38: =(LG26V[[#This Row],["J"PRECIO COMPRA ]]/LG26V[[#This Row],[BARRAS]]) -> 15 | K38: =SUMIF(entradas26[CODIGO],LG26V[[#This Row],[CODIGO ]],entradas26[[CAN JUEGOS ]]) -> 0 | L38: =SUMIF(entradas26[CODIGO],LG26V[[#This Row],[CODIGO ]],entradas26[CAN BARRAS]) -> 0 | M38: =SUMIF(salidas26[[CODIGO ]],LG26V[[#This Row],[CODIGO ]],salidas26[[CANT JUEGOS ]]) -> 0 | N38: =SUMIF(salidas26[[CODIGO ]],LG26V[[#This Row],[CODIGO ]],salidas26[CANT BARRAS]) -> 0 | O38: =(LG26V[[#This Row],["J"PRECIO COMPRA ]]*LG26V[[#This Row],[STOCK JUEGOS]]) -> 0 | P38: =(LG26V[[#This Row],["J" PRECIO VENTA ]]*LG26V[[#This Row],[STOCK JUEGOS]]) -> 0 | Q38: =(LG26V[[#This Row],["B"PRECIO COMPRA]]*LG26V[[#This Row],[STOCK BARRAS]]) -> 90 | R38: =(LG26V[[#This Row],["B"PRECIO VENTA ]]*LG26V[[#This Row],[STOCK BARRAS]]) -> 187.5 | S38: 0 | T38: 6
A39: 35 | B39: 1087 | C39: 49LK5400 /8B | D39: =(LG26V[[#This Row],[CANTIDAD INICIAL JUEGO ]]+LG26V[[#This Row],[ENTRADAS JUEGOS ]]-LG26V[[#This Row],[SALIDAS JUEGOS]]) -> 13 | E39: =(LG26V[[#This Row],[CANTIDAD INICIAL BARRAS]]+LG26V[[#This Row],[ENTRADAS BARRAS]]-LG26V[[#This Row],[SALIDA BARRAS]]) -> 7 | F39: 220 | G39: 114 | H39: 8 | I39: =(LG26V[[#This Row],["J" PRECIO VENTA ]]/LG26V[[#This Row],[BARRAS]]) -> 27.5 | J39: =(LG26V[[#This Row],["J"PRECIO COMPRA ]]/LG26V[[#This Row],[BARRAS]]) -> 14.25 | K39: =SUMIF(entradas26[CODIGO],LG26V[[#This Row],[CODIGO ]],entradas26[[CAN JUEGOS ]]) -> 0 | L39: =SUMIF(entradas26[CODIGO],LG26V[[#This Row],[CODIGO ]],entradas26[CAN BARRAS]) -> 0 | M39: =SUMIF(salidas26[[CODIGO ]],LG26V[[#This Row],[CODIGO ]],salidas26[[CANT JUEGOS ]]) -> 3 | N39: =SUMIF(salidas26[[CODIGO ]],LG26V[[#This Row],[CODIGO ]],salidas26[CANT BARRAS]) -> 0 | O39: =(LG26V[[#This Row],["J"PRECIO COMPRA ]]*LG26V[[#This Row],[STOCK JUEGOS]]) -> 1482 | P39: =(LG26V[[#This Row],["J" PRECIO VENTA ]]*LG26V[[#This Row],[STOCK JUEGOS]]) -> 2860 | Q39: =(LG26V[[#This Row],["B"PRECIO COMPRA]]*LG26V[[#This Row],[STOCK BARRAS]]) -> 99.75 | R39: =(LG26V[[#This Row],["B"PRECIO VENTA ]]*LG26V[[#This Row],[STOCK BARRAS]]) -> 192.5 | S39: 16 | T39: 7 | U39: 5.7 | W39: XLM-W0760
A40: 36 | B40: 1090 | C40: 49UB8300/ 2B | D40: =(LG26V[[#This Row],[CANTIDAD INICIAL JUEGO ]]+LG26V[[#This Row],[ENTRADAS JUEGOS ]]-LG26V[[#This Row],[SALIDAS JUEGOS]]) -> 16 | E40: =(LG26V[[#This Row],[CANTIDAD INICIAL BARRAS]]+LG26V[[#This Row],[ENTRADAS BARRAS]]-LG26V[[#This Row],[SALIDA BARRAS]]) -> 0 | F40: 250 | G40: 63 | H40: 2 | I40: =(LG26V[[#This Row],["J" PRECIO VENTA ]]/LG26V[[#This Row],[BARRAS]]) -> 125 | J40: =(LG26V[[#This Row],["J"PRECIO COMPRA ]]/LG26V[[#This Row],[BARRAS]]) -> 31.5 | K40: =SUMIF(entradas26[CODIGO],LG26V[[#This Row],[CODIGO ]],entradas26[[CAN JUEGOS ]]) -> 0 | L40: =SUMIF(entradas26[CODIGO],LG26V[[#This Row],[CODIGO ]],entradas26[CAN BARRAS]) -> 0 | M40: =SUMIF(salidas26[[CODIGO ]],LG26V[[#This Row],[CODIGO ]],salidas26[[CANT JUEGOS ]]) -> 0 | N40: =SUMIF(salidas26[[CODIGO ]],LG26V[[#This Row],[CODIGO ]],salidas26[CANT BARRAS]) -> 0 | O40: =(LG26V[[#This Row],["J"PRECIO COMPRA ]]*LG26V[[#This Row],[STOCK JUEGOS]]) -> 1008 | P40: =(LG26V[[#This Row],["J" PRECIO VENTA ]]*LG26V[[#This Row],[STOCK JUEGOS]]) -> 4000 | Q40: =(LG26V[[#This Row],["B"PRECIO COMPRA]]*LG26V[[#This Row],[STOCK BARRAS]]) -> 0 | R40: =(LG26V[[#This Row],["B"PRECIO VENTA ]]*LG26V[[#This Row],[STOCK BARRAS]]) -> 0 | S40: 16 | U40: 4.5 | W40: XLM-1019/1020
A41: 37 | B41: 1094 | C41: 49 UH6100-LH5100 /8B | D41: =(LG26V[[#This Row],[CANTIDAD INICIAL JUEGO ]]+LG26V[[#This Row],[ENTRADAS JUEGOS ]]-LG26V[[#This Row],[SALIDAS JUEGOS]]) -> 13 | E41: =(LG26V[[#This Row],[CANTIDAD INICIAL BARRAS]]+LG26V[[#This Row],[ENTRADAS BARRAS]]-LG26V[[#This Row],[SALIDA BARRAS]]) -> 6 | F41: 250 | G41: 96 | H41: 8 | I41: =(LG26V[[#This Row],["J" PRECIO VENTA ]]/LG26V[[#This Row],[BARRAS]]) -> 31.25 | J41: =(LG26V[[#This Row],["J"PRECIO COMPRA ]]/LG26V[[#This Row],[BARRAS]]) -> 12 | K41: =SUMIF(entradas26[CODIGO],LG26V[[#This Row],[CODIGO ]],entradas26[[CAN JUEGOS ]]) -> 0 | L41: =SUMIF(entradas26[CODIGO],LG26V[[#This Row],[CODIGO ]],entradas26[CAN BARRAS]) -> 0 | M41: =SUMIF(salidas26[[CODIGO ]],LG26V[[#This Row],[CODIGO ]],salidas26[[CANT JUEGOS ]]) -> 1 | N41: =SUMIF(salidas26[[CODIGO ]],LG26V[[#This Row],[CODIGO ]],salidas26[CANT BARRAS]) -> 0 | O41: =(LG26V[[#This Row],["J"PRECIO COMPRA ]]*LG26V[[#This Row],[STOCK JUEGOS]]) -> 1248 | P41: =(LG26V[[#This Row],["J" PRECIO VENTA ]]*LG26V[[#This Row],[STOCK JUEGOS]]) -> 3250 | Q41: =(LG26V[[#This Row],["B"PRECIO COMPRA]]*LG26V[[#This Row],[STOCK BARRAS]]) -> 72 | R41: =(LG26V[[#This Row],["B"PRECIO VENTA ]]*LG26V[[#This Row],[STOCK BARRAS]]) -> 187.5 | S41: 14 | T41: 6 | U41: 4.36 | W41: XY-0032
A42: 38 | B42: 1096 | C42: 49LH6000 /8B | D42: =(LG26V[[#This Row],[CANTIDAD INICIAL JUEGO ]]+LG26V[[#This Row],[ENTRADAS JUEGOS ]]-LG26V[[#This Row],[SALIDAS JUEGOS]]) -> 12 | E42: =(LG26V[[#This Row],[CANTIDAD INICIAL BARRAS]]+LG26V[[#This Row],[ENTRADAS BARRAS]]-LG26V[[#This Row],[SALIDA BARRAS]]) -> 0 | F42: 260 | G42: 112 | H42: 8 | I42: =(LG26V[[#This Row],["J" PRECIO VENTA ]]/LG26V[[#This Row],[BARRAS]]) -> 32.5 | J42: =(LG26V[[#This Row],["J"PRECIO COMPRA ]]/LG26V[[#This Row],[BARRAS]]) -> 14 | K42: =SUMIF(entradas26[CODIGO],LG26V[[#This Row],[CODIGO ]],entradas26[[CAN JUEGOS ]]) -> 0 | L42: =SUMIF(entradas26[CODIGO],LG26V[[#This Row],[CODIGO ]],entradas26[CAN BARRAS]) -> 0 | M42: =SUMIF(salidas26[[CODIGO ]],LG26V[[#This Row],[CODIGO ]],salidas26[[CANT JUEGOS ]]) -> 1 | N42: =SUMIF(salidas26[[CODIGO ]],LG26V[[#This Row],[CODIGO ]],salidas26[CANT BARRAS]) -> 0 | O42: =(LG26V[[#This Row],["J"PRECIO COMPRA ]]*LG26V[[#This Row],[STOCK JUEGOS]]) -> 1344 | P42: =(LG26V[[#This Row],["J" PRECIO VENTA ]]*LG26V[[#This Row],[STOCK JUEGOS]]) -> 3120 | Q42: =(LG26V[[#This Row],["B"PRECIO COMPRA]]*LG26V[[#This Row],[STOCK BARRAS]]) -> 0 | R42: =(LG26V[[#This Row],["B"PRECIO VENTA ]]*LG26V[[#This Row],[STOCK BARRAS]]) -> 0 | S42: 13
...

Sheet SAMSUNG
B2: SAMSUNG
B4: CODIGO | C4: DESCRIPCION | D4: STOCK JUEGOS | E4: STOCK BARRAS | F4: "J" PRECIO VENTA | G4: "J"PRECIO COMPRA | H4: BARRAS | I4: "B"PRECIO VENTA | J4: "B"PRECIO COMPRA | K4: ENTRADAS JUEGOS | L4: ENTRADAS BARRAS | M4: SALIDAS JUEGOS | N4: SALIDA BARRAS | O4: CAPITAL JUEGOS | P4: CAPITAL/GANANCIA/JUEGOS | Q4: CAPITAL BARRA | R4: CAP GAN BARRAS | S4: CANTIDAD INICIAL JUEGO | T4: CANTIDAD INICIAL BARRAS | U4: PRECIO EN $ | V4: CODIGO 2 | W4: CODIGO 3 | X4: CODIGO 4
A5: 1 | B5: 2000 | C5: UN32FH4005G-UN32JH4005G CUERNITO 2B | D5: =(samgung26[[#This Row],[CANTIDAD INICIAL JUEGO ]]+samgung26[[#This Row],[ENTRADAS JUEGOS ]]-samgung26[[#This Row],[SALIDAS JUEGOS]]) -> 4 | E5: =(samgung26[[#This Row],[CANTIDAD INICIAL BARRAS]]+samgung26[[#This Row],[ENTRADAS BARRAS]]-samgung26[[#This Row],[SALIDA BARRAS]]) -> 1 | F5: 80 | G5: 37 | H5: 2 | I5: =(samgung26[[#This Row],["J" PRECIO VENTA ]]/samgung26[[#This Row],[BARRAS]]) -> 40 | J5: =(samgung26[[#This Row],["J"PRECIO COMPRA ]]/samgung26[[#This Row],[BARRAS]]) -> 18.5 | K5: =SUMIF(entradas26[CODIGO],samgung26[[#This Row],[CODIGO ]],entradas26[[CAN JUEGOS ]]) -> 0 | L5: =SUMIF(entradas26[CODIGO],samgung26[[#This Row],[CODIGO ]],entradas26[CAN BARRAS]) -> 0 | M5: =SUMIF(salidas26[[CODIGO ]],samgung26[[#This Row],[CODIGO ]],salidas26[[CANT JUEGOS ]]) -> 28 | N5: =SUMIF(salidas26[[CODIGO ]],samgung26[[#This Row],[CODIGO ]],salidas26[CANT BARRAS]) -> 0 | O5: =(samgung26[[#This Row],["J"PRECIO COMPRA ]]*samgung26[[#This Row],[STOCK JUEGOS]]) -> 148 | P5: =(samgung26[[#This Row],["J" PRECIO VENTA ]]*samgung26[[#This Row],[STOCK JUEGOS]]) -> 320 | Q5: =(samgung26[[#This Row],["B"PRECIO COMPRA]]*samgung26[[#This Row],[STOCK BARRAS]]) -> 18.5 | R5: =(samgung26[[#This Row],["B"PRECIO VENTA ]]*samgung26[[#This Row],[STOCK BARRAS]]) -> 40 | S5: 32 | T5: 1 | U5: 1.55 | W5: XLM-0289 | X5: XY-0065
A6: 2 | B6: 2001 | C6: UN32EH4000 4B/3V | D6: =(samgung26[[#This Row],[CANTIDAD INICIAL JUEGO ]]+samgung26[[#This Row],[ENTRADAS JUEGOS ]]-samgung26[[#This Row],[SALIDAS JUEGOS]]) -> 2 | E6: =(samgung26[[#This Row],[CANTIDAD INICIAL BARRAS]]+samgung26[[#This Row],[ENTRADAS BARRAS]]-samgung26[[#This Row],[SALIDA BARRAS]]) -> 0 | F6: 150 | G6: 100 | H6: 4 | I6: =(samgung26[[#This Row],["J" PRECIO VENTA ]]/samgung26[[#This Row],[BARRAS]]) -> 37.5 | J6: =(samgung26[[#This Row],["J"PRECIO COMPRA ]]/samgung26[[#This Row],[BARRAS]]) -> 25 | K6: =SUMIF(entradas26[CODIGO],samgung26[[#This Row],[CODIGO ]],entradas26[[CAN JUEGOS ]]) -> 0 | L6: =SUMIF(entradas26[CODIGO],samgung26[[#This Row],[CODIGO ]],entradas26[CAN BARRAS]) -> 0 | M6: =SUMIF(salidas26[[CODIGO ]],samgung26[[#This Row],[CODIGO ]],salidas26[[CANT JUEGOS ]]) -> 1 | N6: =SUMIF(salidas26[[CODIGO ]],samgung26[[#This Row],[CODIGO ]],salidas26[CANT BARRAS]) -> 0 | O6: =(samgung26[[#This Row],["J"PRECIO COMPRA ]]*samgung26[[#This Row],[STOCK JUEGOS]]) -> 200 | P6: =(samgung26[[#This Row],["J" PRECIO VENTA ]]*samgung26[[#This Row],[STOCK JUEGOS]]) -> 300 | Q6: =(samgung26[[#This Row],["B"PRECIO COMPRA]]*samgung26[[#This Row],[STOCK BARRAS]]) -> 0 | R6: =(samgung26[[#This Row],["B"PRECIO VENTA ]]*samgung26[[#This Row],[STOCK BARRAS]]) -> 0 | S6: 3
A7: 3 | B7: 2003 | C7: UN32F5000-SAMSUNG 5B | D7: =(samgung26[[#This Row],[CANTIDAD INICIAL JUEGO ]]+samgung26[[#This Row],[ENTRADAS JUEGOS ]]-samgung26[[#This Row],[SALIDAS JUEGOS]]) -> 25 | E7: =(samgung26[[#This Row],[CANTIDAD INICIAL BARRAS]]+samgung26[[#This Row],[ENTRADAS BARRAS]]-samgung26[[#This Row],[SALIDA BARRAS]]) -> 3 | F7: 130 | G7: 74 | H7: 5 | I7: =(samgung26[[#This Row],["J" PRECIO VENTA ]]/samgung26[[#This Row],[BARRAS]]) -> 26 | J7: =(samgung26[[#This Row],["J"PRECIO COMPRA ]]/samgung26[[#This Row],[BARRAS]]) -> 14.8 | K7: =SUMIF(entradas26[CODIGO],samgung26[[#This Row],[CODIGO ]],entradas26[[CAN JUEGOS ]]) -> 20 | L7: =SUMIF(entradas26[CODIGO],samgung26[[#This Row],[CODIGO ]],entradas26[CAN BARRAS]) -> 15 | M7: =SUMIF(salidas26[[CODIGO ]],samgung26[[#This Row],[CODIGO ]],salidas26[[CANT JUEGOS ]]) -> 8 | N7: =SUMIF(salidas26[[CODIGO ]],samgung26[[#This Row],[CODIGO ]],salidas26[CANT BARRAS]) -> 14 | O7: =(samgung26[[#This Row],["J"PRECIO COMPRA ]]*samgung26[[#This Row],[STOCK JUEGOS]]) -> 1850 | P7: =(samgung26[[#This Row],["J" PRECIO VENTA ]]*samgung26[[#This Row],[STOCK JUEGOS]]) -> 3250 | Q7: =(samgung26[[#This Row],["B"PRECIO COMPRA]]*samgung26[[#This Row],[STOCK BARRAS]]) -> 44.4 | R7: =(samgung26[[#This Row],["B"PRECIO VENTA ]]*samgung26[[#This Row],[STOCK BARRAS]]) -> 78 | S7: 13 | T7: 2 | U7: 3.9 | V7: poner nombre | W7: XLM-0319
A8: 4 | B8: 2006 | C8: UN32J/ 2B | D8: =(samgung26[[#This Row],[CANTIDAD INICIAL JUEGO ]]+samgung26[[#This Row],[ENTRADAS JUEGOS ]]-samgung26[[#This Row],[SALIDAS JUEGOS]]) -> 18 | E8: =(samgung26[[#This Row],[CANTIDAD INICIAL BARRAS]]+samgung26[[#This Row],[ENTRADAS BARRAS]]-samgung26[[#This Row],[SALIDA BARRAS]]) -> 1 | F8: 90 | G8: 38 | H8: 2 | I8: =(samgung26[[#This Row],["J" PRECIO VENTA ]]/samgung26[[#This Row],[BARRAS]]) -> 45 | J8: =(samgung26[[#This Row],["J"PRECIO COMPRA ]]/samgung26[[#This Row],[BARRAS]]) -> 19 | K8: =SUMIF(entradas26[CODIGO],samgung26[[#This Row],[CODIGO ]],entradas26[[CAN JUEGOS ]]) -> 0 | L8: =SUMIF(entradas26[CODIGO],samgung26[[#This Row],[CODIGO ]],entradas26[CAN BARRAS]) -> 0 | M8: =SUMIF(salidas26[[CODIGO ]],samgung26[[#This Row],[CODIGO ]],salidas26[[CANT JUEGOS ]]) -> 3 | N8: =SUMIF(salidas26[[CODIGO ]],samgung26[[#This Row],[CODIGO ]],salidas26[CANT BARRAS]) -> 0 | O8: =(samgung26[[#This Row],["J"PRECIO COMPRA ]]*samgung26[[#This Row],[STOCK JUEGOS]]) -> 684 | P8: =(samgung26[[#This Row],["J" PRECIO VENTA ]]*samgung26[[#This Row],[STOCK JUEGOS]]) -> 1620 | Q8: =(samgung26[[#This Row],["B"PRECIO COMPRA]]*samgung26[[#This Row],[STOCK BARRAS]]) -> 19 | R8: =(samgung26[[#This Row],["B"PRECIO VENTA ]]*samgung26[[#This Row],[STOCK BARRAS]]) -> 45 | S8: 21 | T8: 1 | U8: 1.6 | W8: XLM-1956
A9: 5 | B9: 2009 | C9: UN40D5500/2B | D9: =(samgung26[[#This Row],[CANTIDAD INICIAL JUEGO ]]+samgung26[[#This Row],[ENTRADAS JUEGOS ]]-samgung26[[#This Row],[SALIDAS JUEGOS]]) -> 19 | E9: =(samgung26[[#This Row],[CANTIDAD INICIAL BARRAS]]+samgung26[[#This Row],[ENTRADAS BARRAS]]-samgung26[[#This Row],[SALIDA BARRAS]]) -> 0 | F9: 180 | G9: 75 | H9: 2 | I9: =(samgung26[[#This Row],["J" PRECIO VENTA ]]/samgung26[[#This Row],[BARRAS]]) -> 90 | J9: =(samgung26[[#This Row],["J"PRECIO COMPRA ]]/samgung26[[#This Row],[BARRAS]]) -> 37.5 | K9: =SUMIF(entradas26[CODIGO],samgung26[[#This Row],[CODIGO ]],entradas26[[CAN JUEGOS ]]) -> 0 | L9: =SUMIF(entradas26[CODIGO],samgung26[[#This Row],[CODIGO ]],entradas26[CAN BARRAS]) -> 0 | M9: =SUMIF(salidas26[[CODIGO ]],samgung26[[#This Row],[CODIGO ]],salidas26[[CANT JUEGOS ]]) -> 0 | N9: =SUMIF(salidas26[[CODIGO ]],samgung26[[#This Row],[CODIGO ]],salidas26[CANT BARRAS]) -> 0 | O9: =(samgung26[[#This Row],["J"PRECIO COMPRA ]]*samgung26[[#This Row],[STOCK JUEGOS]]) -> 1425 | P9: =(samgung26[[#This Row],["J" PRECIO VENTA ]]*samgung26[[#This Row],[STOCK JUEGOS]]) -> 3420 | Q9: =(samgung26[[#This Row],["B"PRECIO COMPRA]]*samgung26[[#This Row],[STOCK BARRAS]]) -> 0 | R9: =(samgung26[[#This Row],["B"PRECIO VENTA ]]*samgung26[[#This Row],[STOCK BARRAS]]) -> 0 | S9: 19 | U9: 3.55 | W9: XLM-0178/0179
B10: 2008 | C10: UN 40 D6500/2B | D10: =(samgung26[[#This Row],[CANTIDAD INICIAL JUEGO ]]+samgung26[[#This Row],[ENTRADAS JUEGOS ]]-samgung26[[#This Row],[SALIDAS JUEGOS]]) -> 10 | E10: =(samgung26[[#This Row],[CANTIDAD INICIAL BARRAS]]+samgung26[[#This Row],[ENTRADAS BARRAS]]-samgung26[[#This Row],[SALIDA BARRAS]]) -> 0 | F10: 200 | G10: 103 | I10: =(samgung26[[#This Row],["J" PRECIO VENTA ]]/samgung26[[#This Row],[BARRAS]]) -> #DIV/0! | J10: =(samgung26[[#This Row],["J"PRECIO COMPRA ]]/samgung26[[#This Row],[BARRAS]]) -> #DIV/0! | K10: =SUMIF(entradas26[CODIGO],samgung26[[#This Row],[CODIGO ]],entradas26[[CAN JUEGOS ]]) -> 10 | L10: =SUMIF(entradas26[CODIGO],samgung26[[#This Row],[CODIGO ]],entradas26[CAN BARRAS]) -> 0 | M10: =SUMIF(salidas26[[CODIGO ]],samgung26[[#This Row],[CODIGO ]],salidas26[[CANT JUEGOS ]]) -> 0 | N10: =SUMIF(salidas26[[CODIGO ]],samgung26[[#This Row],[CODIGO ]],salidas26[CANT BARRAS]) -> 0 | O10: =(samgung26[[#This Row],["J"PRECIO COMPRA ]]*samgung26[[#This Row],[STOCK JUEGOS]]) -> 1030 | P10: =(samgung26[[#This Row],["J" PRECIO VENTA ]]*samgung26[[#This Row],[STOCK JUEGOS]]) -> 2000 | Q10: =(samgung26[[#This Row],["B"PRECIO COMPRA]]*samgung26[[#This Row],[STOCK BARRAS]]) -> #DIV/0! | R10: =(samgung26[[#This Row],["B"PRECIO VENTA ]]*samgung26[[#This Row],[STOCK BARRAS]]) -> #DIV/0! | U10: 5.4 | W10: XLM - W0896
A11: 6 | B11: 2012 | C11: UN40J5000 -40J5200-40M5000 8L/3B | D11: =(samgung26[[#This Row],[CANTIDAD INICIAL JUEGO ]]+samgung26[[#This Row],[ENTRADAS JUEGOS ]]-samgung26[[#This Row],[SALIDAS JUEGOS]]) -> 14 | E11: =(samgung26[[#This Row],[CANTIDAD INICIAL BARRAS]]+samgung26[[#This Row],[ENTRADAS BARRAS]]-samgung26[[#This Row],[SALIDA BARRAS]]) -> 0 | F11: 160 | G11: 62 | H11: 3 | I11: =(samgung26[[#This Row],["J" PRECIO VENTA ]]/samgung26[[#This Row],[BARRAS]]) -> 53.333333 | J11: =(samgung26[[#This Row],["J"PRECIO COMPRA ]]/samgung26[[#This Row],[BARRAS]]) -> 20.666667 | K11: =SUMIF(entradas26[CODIGO],samgung26[[#This Row],[CODIGO ]],entradas26[[CAN JUEGOS ]]) -> 0 | L11: =SUMIF(entradas26[CODIGO],samgung26[[#This Row],[CODIGO ]],entradas26[CAN BARRAS]) -> 0 | M11: =SUMIF(salidas26[[CODIGO ]],samgung26[[#This Row],[CODIGO ]],salidas26[[CANT JUEGOS ]]) -> 10 | N11: =SUMIF(salidas26[[CODIGO ]],samgung26[[#This Row],[CODIGO ]],salidas26[CANT BARRAS]) -> 0 | O11: =(samgung26[[#This Row],["J"PRECIO COMPRA ]]*samgung26[[#This Row],[STOCK JUEGOS]]) -> 868 | P11: =(samgung26[[#This Row],["J" PRECIO VENTA ]]*samgung26[[#This Row],[STOCK JUEGOS]]) -> 2240 | Q11: =(samgung26[[#This Row],["B"PRECIO COMPRA]]*samgung26[[#This Row],[STOCK BARRAS]]) -> 0 | R11: =(samgung26[[#This Row],["B"PRECIO VENTA ]]*samgung26[[#This Row],[STOCK BARRAS]]) -> 0 | S11: 24 | U11: 3.4 | W11: XLM-0306
